Workbook
Name округл: #REF!
Name округл: #REF!
Name округл: #REF!

Sheet 1M
B1: ПОСТАВЩИК: ООО ФИРМА "СИГНАЛ"
B2: адрес: 364031, Чеченская Республика, г.Грозный, ул. Жуковского, д. 18
C4: Заказ-наряд № 100528 от 08.06.2026
B6: Заказчик: Общество с ограниченной ответственностью «Концепт» | H6: адрес заказчика : 364024, ЧР г.Грозный, ул.Назарбаева, д.92, оф. 6-05
B7: Автомобиль : УАЗ Патриот г/н О 201 МК/126
B9: Цена автомототранспортного средства, определяемая по соглашению сторон __________________
B11: Плательщик: Общество с ограниченной ответственностью «Концепт»
B12: ИНН 2014030866 адрес: телефоны: +7 (989) 9002252
N14: в валюте
N15: Руб
C17: Выполненные работы по заказ-наряду № 100528 от 08.06.2026
B19: № | C19: № кат. | D19: Наименование | I19: Кол. оп. | J19: Цена | K19: Норма | L19: н/ч | M19: Всего | N19: в т.ч. НДС
B20: 1 | C20: 2 | D20: 3 | I20: 4 | J20: 5 | K20: 6 | L20: 7 | M20: 8 | N20: 9
B21: 1 | D21: Ремонт КПП со снятием и установкой | I21: 1 | J21: 15000 | K21: 1 | L21: Рубль | M21: =J21*I21 -> 15000 | N21: =M21*22/122 -> 2704.918
B22: Итого работ: | I22: 1 | J22: на сумму: | M22: =M21 -> 15000 | N22: =M22*22/122 -> 2704.918
B24: Пятнадцать тысяч рублей 00 копеек.
C26: Расходная накладная к заказ-наряду № 100528 от 08.06.2026
B28: № | C28: № кат. | D28: Наименование | J28: Кол-во | K28: Ед.изм. | L28: Цена | M28: Всего | N28: в т.ч. НДС
B29: 1 | C29: 2 | D29: 3 | J29: 4 | K29: 5 | L29: 6 | M29: 7 | N29: 8
B30: 1 | C30: 3590973 | D30: Масло трансмиссионное LUKOIL GEAR GL-4 75W-90 4л. | J30: 1 | K30: шт | L30: 3000 | M30: =L30*J30 -> 3000 | N30: =M30*22/122 -> 540.98361
B31: 2 | C31: 3590970 | D31: Масло трансмиссионное LUKOIL GEAR GL-4 75W-90 1л. | J31: 1 | K31: шт | L31: 800 | M31: =L31*J31 -> 800 | N31: =M31*22/122 -> 144.2623
B32: Итого материалов: | J32: 2 | K32: на сумму: | M32: =M30+M31 -> 3800 | N32: =M32*22/122 -> 685.2459
B34: Три тысячи восемьсот рублей 00 копеек
L36: Итого по заказ-наряду : | M36: =M22+M32 -> 18800 | N36: =M36*22/122 -> 3390.1639
B38: Всего по заказ-наряду: Восемнадцать тысяч восемьсот рублей 00 копеек, в т.ч. НДС 22%.
J41: Мастер _____________________ | K41: Механик СТО/
C43: Гарантии: Гарантия на работы: слесарные - 30 дней, электрические - 30 дней, оригинальные з/ч - 30 дней, з/ч, связанные с электрооборудованием, подачей топлива и системой впрыска - гарантии нет, неоригинальные з/ч - гарантии нет. Гарантийные обязательства на работы выполняются фирмой только при предъявлении акта приемки автомобиля и техпаспорта (доверенности).
B47: Дата: 08.06.2026 | J47: Заказчик ______________________ | K47: /ООО «Концепт»/
J49: Плательщик ______________________ | K49: /ООО «Концепт»/
B51: Причина обращения:

Sheet 001
A1: Общество с ограниченной ответственностью "КОНЦЕПТ"
A2: 364024, Чеченская Республика г. Грозный, ул. Назарбаева, д. 92, оф. 6-05
A4: Заказ-наряд № | D4: 001-20 | E4: от | F4: 46174 | I4: Дата начала работ | K4: 46174
A5: Основание Государственный контракт № 03101000048260000200001 | I5: Дата окончания | K5: 46174
A6: от 01.06.2026г. ИГК 2627188100202002632098795
A8: Заказчик: ЦОУ ВОГОиП МВД России ГУ МВД России по СКФО | I8: VIN № | J8: XTT316300R1000091
I9: Кузов №
A10: Адрес: 363751, Северная Осетия-Алания Респ, ул.Усанова стр.30. | I10: Гос.№ | J10: О201МК126
I11: Год выпуска | K11: 2023
A12: ИНН2632098795 | C12: КПП151043001 | I12: Марка, модель ТС | K12: УАЗ UAZ PATRIOT 3163
A13: Телефон 8-867-36-90-11-8 | I13: Пробег | J13: 4116
I14: Особые данные | K14: гараж.№ | L14: 106-81
A15: Выполненные работы по Заказ-наряду № | H15: 001-20 | I15: от | J15: 46174
A16: № | B16: Код операции | C16: Выполненные работы | G16: Кол-во н/ч | H16: Вид ремонта | I16: Кол-во оп. | J16: Цена н/ч | K16: Ед.изм. | L16: Сумма
A17: 1 | B17: 0000123 | C17: Коробка передач - проверка работы | G17: 0.8 | H17: Обычный | I17: 1 | J17: 2433.33 | K17: н/ч | L17: 1946.66
A18: 2 | B18: 0000210 | C18: Коробка передач - замена масла | G18: 0,25 | H18: Обычный | I18: 1 | J18: 2433.33 | K18: н/ч | L18: 608.33
A19: 3 | B19: 1700001 | C19: Коробка передач, раздаточная коробка и стояночный тормоз в сборе - снятие и установка | G19: 8.75 | H19: Обычный | I19: 1 | J19: 2433.33 | K19: н/ч | L19: 21291.64
A20: 4 | B20: 1700002 | C20: Рычаг переключения передач - снятие и установка | G20: 0.2 | H20: Обычный | I20: 1 | J20: 2433.33 | K20: н/ч | L20: 486.67
A21: 5 | B21: 1700003 | C21: Коробка передач - снятие и установка (при снятом агрегате) | G21: 2.04 | H21: Обычный | I21: 1 | J21: 2433.33 | K21: н/ч | L21: 4963.99
A22: 6 | B22: 1700004 | C22: Коробка передач - ремонт (без разборки вторичного вала) | G22: 3.9 | H22: Обычный | I22: 1 | J22: 2433.33 | K22: н/ч | L22: 9489.99
A23: 7 | B23: 1700009 | C23: Картер КП передний - снятие и установка | G23: 1.06 | H23: Обычный | I23: 1 | J23: 2433.33 | K23: н/ч | L23: 2579.33
A24: 8 | B24: 1700010 | C24: Вал вторичный - снятие и установка (при снятом переднем картере КП) | G24: 0.65 | H24: Обычный | I24: 1 | J24: 2433.33 | K24: н/ч | L24: 1581.66
A25: 9 | B25: 2800011 | C25: Брызговик КП и РК - снятие и установка. | G25: 0.4 | H25: Обычный | I25: 1 | J25: 2433.33 | K25: н/ч | L25: 973.33
A26: 10 | B26: 0 | C26: 0 | G26: 0 | H26: Обычный | I26: 0 | J26: 2433.33 | K26: н/ч | L26: 0
A27: 11 | B27: 0 | C27: 0 | G27: 0 | H27: Обычный | I27: 0 | J27: 2433.33 | K27: н/ч | L27: 0
A28: 12 | B28: 0 | C28: 0 | G28: 0 | H28: Обычный | I28: 0 | J28: 2433.33 | K28: н/ч | L28: 0
A29: 13 | B29: 0 | C29: 0 | G29: 0 | H29: Обычный | I29: 0 | J29: 0 | K29: н/ч | L29: 0
A30: 14 | B30: 0 | C30: 0 | G30: 0 | H30: Обычный | I30: 0 | J30: 0 | K30: н/ч | L30: 0
A31: 15 | B31: 0 | C31: 0 | G31: 0 | H31: Обычный | I31: 0 | J31: 0 | K31: н/ч | L31: 0
A32: 16 | B32: 0 | C32: 0 | G32: 0 | H32: Обычный | I32: 0 | J32: 0 | K32: н/ч | L32: 0
A33: 17 | B33: 0 | C33: 0 | G33: 0 | H33: Обычный | I33: 0 | J33: 0 | K33: н/ч | L33: 0
A34: 18 | B34: 0 | C34: 0 | G34: 0 | H34: Обычный | I34: 0 | J34: 0 | K34: н/ч | L34: 0
A35: 19 | B35: 0 | C35: 0 | G35: 0 | H35: Обычный | I35: 0 | J35: 0 | K35: н/ч | L35: 0
A36: 20 | B36: 0 | C36: 0 | G36: 0 | H36: Обычный | I36: 0 | J36: 0 | K36: н/ч | L36: 0
A37: 21 | B37: 0 | C37: 0 | G37: 0 | H37: Обычный | I37: 0 | J37: 0 | K37: н/ч | L37: 0
... A79: 63 | B79: 0 | C79: 0 | G79: 0 | H79: Обычный | I79: 0 | J79: 0 | K79: н/ч | L79: 0
A80: 64 | C80: 0 | G80: 0 | H80: Обычный | I80: 0 | J80: 0 | K80: н/ч | L80: 0
A81: 65 | C81: 0 | I81: 0 | J81: 0
A82: 66 | C82: 0 | I82: 0 | J82: 0
A83: 67 | C83: 0 | I83: 0 | J83: 0
...

Sheet 2M
B1: ПОСТАВЩИК: ООО ФИРМА "СИГНАЛ"
B2: адрес: 364031, Чеченская Республика, г.Грозный, ул. Жуковского, д. 18
C4: Заказ-наряд № 100517 от 05.06.2026
B6: Заказчик: Общество с ограниченной ответственностью «Концепт» | H6: адрес заказчика : 364024, ЧР г.Грозный, ул.Назарбаева, д.92, оф. 6-05
B7: Автомобиль : Лада Веста г/н Е 833 ОЕ/15
B9: Цена автомототранспортного средства, определяемая по соглашению сторон __________________
B11: Плательщик: Общество с ограниченной ответственностью «Концепт»
B12: ИНН 2014030866 адрес: телефоны: +7 (989) 9002252
N14: в валюте
N15: Руб
C17: Выполненные работы по заказ-наряду № 100517 от 05.06.2026
B19: № | C19: № кат. | D19: Наименование | I19: Кол. оп. | J19: Цена | K19: Норма | L19: н/ч | M19: Всего | N19: в т.ч. НДС
B20: 1 | C20: 2 | D20: 3 | I20: 4 | J20: 5 | K20: 6 | L20: 7 | M20: 8 | N20: 9
B21: 1 | D21: Ремонт ДВС | I21: 1 | J21: 25000 | K21: 1 | L21: Рубль | M21: =J21*I21 -> 25000 | N21: =M21*22/122 -> 4508.1967
B22: 2 | D22: Мойка ДВС в разобранном виде | I22: 1 | J22: 4000 | K22: 1 | L22: Рубль | M22: =J22*I22 -> 4000 | N22: =M22*22/122 -> 721.31148
B23: 3 | D23: Расточка блока цилиндров | I23: 1 | J23: 6000 | K23: 1 | L23: Рубль | M23: =J23*I23 -> 6000 | N23: =M23*22/122 -> 1081.9672
B24: 4 | D24: Ремонт ГБЦ | I24: 1 | J24: 4500 | K24: 1 | L24: Рубль | M24: =J24*I24 -> 4500 | N24: =M24*22/122 -> 811.47541
B25: 5 | D25: Замена подшипника опоры амортизатора | I25: 2 | J25: 1800 | K25: 1 | L25: Рубль | M25: =J25*I25 -> 3600 | N25: =M25*22/122 -> 649.18033
B26: 6 | D26: Замена пер-х торм-х колодок | I26: 1 | J26: 600 | K26: 1 | L26: Рубль | M26: =J26*I26 -> 600 | N26: =M26*22/122 -> 108.19672
B27: 7 | D27: Диагностика ДВС | I27: 1 | J27: 1500 | K27: 1 | L27: Рубль | M27: =J27*I27 -> 1500 | N27: =M27*22/122 -> 270.4918
B28: Итого работ: | I28: 8 | J28: на сумму: | M28: =M21+M22+M23+M24+M25+M26+M27 -> 45200 | N28: =M28*22/122 -> 8150.8197
B30: Сорок пять тысяч двести рублей 00 копеек.
C32: Расходная накладная к заказ-наряду № 100517 от 05.06.2026
B34: № | C34: № кат. | D34: Наименование | J34: Кол-во | K34: Ед.изм. | L34: Цена | M34: Всего | N34: в т.ч. НДС
B35: 1 | C35: 2 | D35: 3 | J35: 4 | K35: 5 | L35: 6 | M35: 7 | N35: 8
B36: 1 | C36: 21127.100401557.WPR01 | D36: Поршень ВАЗ 21126 Priora (82.5 A, 1.6L 16V) с пальцем Federal Reserve (кт 4 шт) | J36: 1 | K36: шт | L36: 4500 | M36: =L36*J36 -> 4500 | N36: =M36*22/122 -> 811.47541
B37: 2 | C37: 2112100702603 | D37: Колпачок маслосъемный ВАЗ 2110-12 (16V) Federal Reserve кт 16 шт. | J37: 1 | K37: шт | L37: 800 | M37: =L37*J37 -> 800 | N37: =M37*22/122 -> 144.2623
B38: 3 | C38: 813365310 | D38: Сальник распредвала/коленвала передний Lada/Лада Приора, 2170 Victor Reinz (28х42х7) | J38: 3 | K38: шт | L38: 150 | M38: =L38*J38 -> 450 | N38: =M38*22/122 -> 81.147541
B39: 4 | C39: 2108-1005160-01 | D39: Сальник коленвала дв.406 задний (80х100х10) (Rubena) | J39: 1 | K39: шт | L39: 500 | M39: =L39*J39 -> 500 | N39: =M39*22/122 -> 90.163934
B40: 5 | C40: 11226 | D40: Герметик-прокладка силиконовый АВТОСИЛ черный | J40: 1 | K40: шт | L40: 100 | M40: =L40*J40 -> 100 | N40: =M40*22/122 -> 18.032787
B41: 6 | D41: Опора ресивера ВАЗ 2112 16 кл. | J41: 2 | K41: шт | L41: 150 | M41: =L41*J41 -> 300 | N41: =M41*22/122 -> 54.098361
B42: 7 | C42: 21081010075Р | D42: Кольцо ВАЗ-2108 маслоприемника уплотнительное БРТ | J42: 1 | K42: шт | L42: 30 | M42: =L42*J42 -> 30 | N42: =M42*22/122 -> 5.4098361
B43: 8 | C43: 2112-1004081 | D43: Форсунки масляные на ВАЗ 2112-2170, (к-т 4 шт) | J43: 1 | K43: кт | L43: 500 | M43: =L43*J43 -> 500 | N43: =M43*22/122 -> 90.163934
B44: 9 | D44: Кольцо уплотнительное форсунок ВАЗ 106 л.с. (кт 8 шт) | J44: 1 | K44: кт | L44: 100 | M44: =L44*J44 -> 100 | N44: =M44*22/122 -> 18.032787
B45: 10 | D45: Вкладыши ВАЗ-11194,21116-21127 Приора шатунные d+0.00 ДАЙДО МЕТАЛЛ РУСЬ | J45: 1 | K45: кт | L45: 600 | M45: =L45*J45 -> 600 | N45: =M45*22/122 -> 108.19672
B46: 11 | C46: K015631XS | D46: Комплект ГРМ Приора, Лада Ларгус, Веста, Х Рей, GATES K015631XS (дв. ВАЗ, 16 клапанов) | J46: 1 | K46: кт | L46: 6900 | M46: =L46*J46 -> 6900 | N46: =M46*22/122 -> 1244.2623
B47: 12 | C47: FR518 | D47: Фланцевый герметик в шприце LOCTITE FR518 50 Federal Reserve | J47: 1 | K47: шт | L47: 300 | M47: =L47*J47 -> 300 | N47: =M47*22/122 -> 54.098361
B48: 13 | C48: 2112-1014056Р | D48: Шланг сапуна вытяжной ВАЗ-2112 вентиляции картера БРТ низ. | J48: 1 | K48: шт | L48: 270 | M48: =L48*J48 -> 270 | N48: =M48*22/122 -> 48.688525
B49: 14 | C49: EK.2.7 | D49: Прокладка приемной трубы ВАЗ 21114, 1118, 2170, 2190 металл с перфорацией (треугольник) | J49: 1 | K49: шт | L49: 100 | M49: =L49*J49 -> 100 | N49: =M49*22/122 -> 18.032787
B50: 15 | C50: 2108-012 М | D50: Набор прокладок на двигатель ВАЗ 2108 малый с герметиком "БЦМ" | J50: 1 | K50: шт | L50: 350 | M50: =L50*J50 -> 350 | N50: =M50*22/122 -> 63.114754
...

Sheet report
A1: Номер п/п | B1: Цена н/ч | C1: Марка/Модель | D1: ГЗН | E1: VIN | F1: Пробег | G1: Год вып. | H1: Дата | I1: Гараж. Номер | J1: Номер/месяц | K1: Номер ЗН | L1: Номер/год | M1: Номер ММ | N1: РАБОТЫ | O1: З/Ч | P1: ИТОГО РАСХОД | Q1: РАБОТЫ | R1: З/Ч | S1: ИТОГО ВЫРУЧКА | T1: Рубль | U1: % | V1: Рубль | W1: % | X1: ВАЛОВАЯ ПРИБЫЛЬ | Y1: %
A2: 1 | C2: =spisok!B2 -> УАЗ UAZ PATRIOT 3163 | D2: =spisok!C2 -> О201МК126 | E2: =spisok!D2 -> XTT316300R1000091 | F2: =spisok!G2 -> 4116 | G2: =spisok!F2 -> 2023 | H2: =spisok!H2 -> 46174 | I2: =spisok!E2 -> 106-81 | J2: 1 | K2: 001-10 | L2: 1 | P2: =Таблица6[[#This Row],[Столбец11]]+Таблица6[[#This Row],[Столбец12]] -> 0 | S2: =Таблица6[[#This Row],[Столбец14]]+Таблица6[[#This Row],[Столбец15]] -> 0 | T2: =Таблица6[[#This Row],[Столбец14]]-Таблица6[[#This Row],[Столбец11]] -> 0 | U2: =Таблица6[[#This Row],[Столбец17]]/Таблица6[[#This Row],[Столбец11]] -> #DIV/0! | V2: =Таблица6[[#This Row],[Столбец15]]-Таблица6[[#This Row],[Столбец12]] -> 0 | W2: =Таблица6[[#This Row],[Столбец19]]/Таблица6[[#This Row],[Столбец12]] -> #DIV/0! | X2: =Таблица6[[#This Row],[Столбец16]]-Таблица6[[#This Row],[Столбец13]] -> 0 | Y2: =Таблица6[[#This Row],[Столбец21]]/Таблица6[[#This Row],[Столбец13]] -> #DIV/0!
A3: 2 | C3: =spisok!B3 -> LADA VESTA GFL110 | D3: =spisok!C3 -> Е833ОЕ15 | E3: =spisok!D3 -> XTAGFL110LY378838 | F3: =spisok!G3 -> 237856 | G3: =spisok!F3 -> 2019 | H3: =spisok!H3 -> 46175 | I3: =spisok!E3 -> 104-61 | J3: 2 | K3: 002-10 | L3: 2 | P3: =Таблица6[[#This Row],[Столбец11]]+Таблица6[[#This Row],[Столбец12]] -> 0 | X3: =Таблица6[[#This Row],[Столбец16]]-Таблица6[[#This Row],[Столбец13]] -> 0 | Y3: =Таблица6[[#This Row],[Столбец21]]/Таблица6[[#This Row],[Столбец13]] -> #DIV/0!
A4: 3 | C4: =spisok!B4 -> ЕСАУЛ 394511-03 | D4: =spisok!C4 -> В723УУ15 | E4: =spisok!D4 -> X8939451CG0AK5370 | F4: =spisok!G4 -> 142626 | G4: =spisok!F4 -> 2016 | H4: =spisok!H4 -> 46175 | I4: =spisok!E4 -> 103-30 | J4: 3 | K4: ="00"&TEXT($L4,"0")&"-10" -> 003-10 | L4: 3 | P4: =Таблица6[[#This Row],[Столбец11]]+Таблица6[[#This Row],[Столбец12]] -> 0 | X4: =Таблица6[[#This Row],[Столбец16]]-Таблица6[[#This Row],[Столбец13]] -> 0 | Y4: =Таблица6[[#This Row],[Столбец21]]/Таблица6[[#This Row],[Столбец13]] -> #DIV/0!
A5: 4 | C5: =spisok!B5 -> LADA VESTA GFL110 | D5: =spisok!C5 -> Е378ОУ15 | E5: =spisok!D5 -> XTAGFL110LY443715 | F5: =spisok!G5 -> 209733 | G5: =spisok!F5 -> 2020 | H5: =spisok!H5 -> 46176 | I5: =spisok!E5 -> 105-48 | J5: 4 | K5: ="00"&TEXT($L5,"0")&"-10" -> 004-10 | L5: 4 | P5: =Таблица6[[#This Row],[Столбец11]]+Таблица6[[#This Row],[Столбец12]] -> 0 | X5: =Таблица6[[#This Row],[Столбец16]]-Таблица6[[#This Row],[Столбец13]] -> 0 | Y5: =Таблица6[[#This Row],[Столбец21]]/Таблица6[[#This Row],[Столбец13]] -> #DIV/0!
A6: 5 | C6: =spisok!B6 -> ЕСАУЛ 394511-03 | D6: =spisok!C6 -> Е506НТ15 | E6: =spisok!D6 -> X8939451CK0AK5346 | F6: =spisok!G6 -> 138364 | G6: =spisok!F6 -> 2019 | H6: =spisok!H6 -> 46176 | I6: =spisok!E6 -> 104-91 | J6: 5 | K6: ="00"&TEXT($L6,"0")&"-10" -> 005-10 | L6: 5 | P6: =Таблица6[[#This Row],[Столбец11]]+Таблица6[[#This Row],[Столбец12]] -> 0 | X6: =Таблица6[[#This Row],[Столбец16]]-Таблица6[[#This Row],[Столбец13]] -> 0 | Y6: =Таблица6[[#This Row],[Столбец21]]/Таблица6[[#This Row],[Столбец13]] -> #DIV/0!
A7: 6 | C7: =spisok!B7 -> LADA VESTA GFL110 | D7: =spisok!C7 -> В211ОХ15 | E7: =spisok!D7 -> XTAGFL110JY197249 | F7: =spisok!G7 -> 320689 | G7: =spisok!F7 -> 2018 | H7: =spisok!H7 -> 46176 | I7: =spisok!E7 -> 103-75 | J7: 6 | K7: ="00"&TEXT($L7,"0")&"-10" -> 006-10 | L7: 6 | P7: =Таблица6[[#This Row],[Столбец11]]+Таблица6[[#This Row],[Столбец12]] -> 0 | X7: =Таблица6[[#This Row],[Столбец16]]-Таблица6[[#This Row],[Столбец13]] -> 0 | Y7: =Таблица6[[#This Row],[Столбец21]]/Таблица6[[#This Row],[Столбец13]] -> #DIV/0!
A8: 7 | C8: =spisok!B8 -> TOYOTA CAMRY ASV70L-RE | D8: =spisok!C8 -> Е778РА15 | E8: =spisok!D8 -> XW7BF4HK905167068 | F8: =spisok!G8 -> 40010 | G8: =spisok!F8 -> 2020 | H8: =spisok!H8 -> 46176 | I8: =spisok!E8 -> 106-39 | J8: 7 | K8: ="00"&TEXT($L8,"0")&"-10" -> 007-10 | L8: 7 | P8: =Таблица6[[#This Row],[Столбец11]]+Таблица6[[#This Row],[Столбец12]] -> 0 | X8: =Таблица6[[#This Row],[Столбец16]]-Таблица6[[#This Row],[Столбец13]] -> 0 | Y8: =Таблица6[[#This Row],[Столбец21]]/Таблица6[[#This Row],[Столбец13]] -> #DIV/0!
A9: 8 | C9: =spisok!B9 -> ЛАДА ГРАНТА 219010 | D9: =spisok!C9 -> А287АР126 | E9: =spisok!D9 -> XTA219010E0256411 | F9: =spisok!G9 -> 356419 | G9: =spisok!F9 -> 2014 | H9: =spisok!H9 -> 46177 | I9: =spisok!E9 -> 106-34 | J9: 8 | K9: ="00"&TEXT($L9,"0")&"-10" -> 008-10 | L9: 8 | P9: =Таблица6[[#This Row],[Столбец11]]+Таблица6[[#This Row],[Столбец12]] -> 0 | X9: =Таблица6[[#This Row],[Столбец16]]-Таблица6[[#This Row],[Столбец13]] -> 0 | Y9: =Таблица6[[#This Row],[Столбец21]]/Таблица6[[#This Row],[Столбец13]] -> #DIV/0!
A10: 9 | C10: =spisok!B10 -> LADA 4x4 213100 | D10: =spisok!C10 -> О 0708/15 | E10: =spisok!D10 -> XTA213100L0213886 | F10: =spisok!G10 -> 126256 | G10: =spisok!F10 -> 2019 | H10: =spisok!H10 -> 46177 | I10: =spisok!E10 -> 104-90 | J10: 9 | K10: ="00"&TEXT($L10,"0")&"-10" -> 009-10 | L10: 9 | P10: =Таблица6[[#This Row],[Столбец11]]+Таблица6[[#This Row],[Столбец12]] -> 0 | X10: =Таблица6[[#This Row],[Столбец16]]-Таблица6[[#This Row],[Столбец13]] -> 0 | Y10: =Таблица6[[#This Row],[Столбец21]]/Таблица6[[#This Row],[Столбец13]] -> #DIV/0!
A11: 10 | C11: =spisok!B11 -> LADA PRIORA 217050 | D11: =spisok!C11 -> Т158АЕ15 | E11: =spisok!D11 -> XTA217050G0529350 | F11: =spisok!G11 -> 275410 | G11: =spisok!F11 -> 2015 | H11: =spisok!H11 -> 46177 | I11: =spisok!E11 -> 102-89 | J11: 10 | K11: ="00"&TEXT($L11,"0")&"-10" -> 0010-10 | L11: 10 | P11: =Таблица6[[#This Row],[Столбец11]]+Таблица6[[#This Row],[Столбец12]] -> 0 | X11: =Таблица6[[#This Row],[Столбец16]]-Таблица6[[#This Row],[Столбец13]] -> 0 | Y11: =Таблица6[[#This Row],[Столбец21]]/Таблица6[[#This Row],[Столбец13]] -> #DIV/0!
A12: 11 | C12: =spisok!B12 -> ТОЙОТА КАМРИ | D12: =spisok!C12 -> Е898НТ15 | E12: =spisok!D12 -> XW7BF4FK10S155841 | F12: =spisok!G12 -> 176666 | G12: =spisok!F12 -> 2017 | H12: =spisok!H12 -> 46177 | I12: =spisok!E12 -> 103-69 | J12: 11 | K12: ="00"&TEXT($L12,"0")&"-10" -> 0011-10 | L12: 11 | P12: =Таблица6[[#This Row],[Столбец11]]+Таблица6[[#This Row],[Столбец12]] -> 0 | X12: =Таблица6[[#This Row],[Столбец16]]-Таблица6[[#This Row],[Столбец13]] -> 0 | Y12: =Таблица6[[#This Row],[Столбец21]]/Таблица6[[#This Row],[Столбец13]] -> #DIV/0!
A13: 12 | C13: =spisok!B13 -> УАЗ 396221 3163 | D13: =spisok!C13 -> Е312РА15 | E13: =spisok!D13 -> XTT316300M1002503 | F13: =spisok!G13 -> 108974 | G13: =spisok!F13 -> 2020 | H13: =spisok!H13 -> 46178 | I13: =spisok!E13 -> 105-57 | J13: 12 | K13: ="00"&TEXT($L13,"0")&"-10" -> 0012-10 | L13: 12 | P13: =Таблица6[[#This Row],[Столбец11]]+Таблица6[[#This Row],[Столбец12]] -> 0 | X13: =Таблица6[[#This Row],[Столбец16]]-Таблица6[[#This Row],[Столбец13]] -> 0 | Y13: =Таблица6[[#This Row],[Столбец21]]/Таблица6[[#This Row],[Столбец13]] -> #DIV/0!
A14: 13 | C14: =spisok!B14 -> ЕСАУЛ 394511-03 | D14: =spisok!C14 -> Е368НТ15 | E14: =spisok!D14 -> X8939451CK0AK5323 | F14: =spisok!G14 -> 138585 | G14: =spisok!F14 -> 2019 | H14: =spisok!H14 -> 46178 | I14: =spisok!E14 -> 104-95 | J14: 13 | K14: ="00"&TEXT($L14,"0")&"-10" -> 0013-10 | L14: 13 | P14: =Таблица6[[#This Row],[Столбец11]]+Таблица6[[#This Row],[Столбец12]] -> 0 | X14: =Таблица6[[#This Row],[Столбец16]]-Таблица6[[#This Row],[Столбец13]] -> 0 | Y14: =Таблица6[[#This Row],[Столбец21]]/Таблица6[[#This Row],[Столбец13]] -> #DIV/0!
A15: 14 | C15: =spisok!B15 -> ЕСАУЛ 394511-03 | D15: =spisok!C15 -> Е546НТ15 | E15: =spisok!D15 -> X8939451CK0AK5318 | F15: =spisok!G15 -> 132853 | G15: =spisok!F15 -> 2019 | H15: =spisok!H15 -> 46178 | I15: =spisok!E15 -> 104-96 | J15: 14 | K15: ="00"&TEXT($L15,"0")&"-10" -> 0014-10 | L15: 14 | P15: =Таблица6[[#This Row],[Столбец11]]+Таблица6[[#This Row],[Столбец12]] -> 0 | X15: =Таблица6[[#This Row],[Столбец16]]-Таблица6[[#This Row],[Столбец13]] -> 0 | Y15: =Таблица6[[#This Row],[Столбец21]]/Таблица6[[#This Row],[Столбец13]] -> #DIV/0!
... A31: 30 | C31: =spisok!B31 -> УАЗ ПАТРИОТ | D31: =spisok!C31 -> В787ОХ15 | E31: =spisok!D31 -> XTT316300J1023444 | F31: =spisok!G31 -> 232487 | G31: =spisok!F31 -> 2018 | H31: =spisok!H31 -> 46184 | I31: =spisok!E31 -> 103-91 | J31: 30 | K31: ="00"&TEXT($L31,"0")&"-10" -> 0030-10 | L31: 30 | P31: =Таблица6[[#This Row],[Столбец11]]+Таблица6[[#This Row],[Столбец12]] -> 0 | X31: =Таблица6[[#This Row],[Столбец16]]-Таблица6[[#This Row],[Столбец13]] -> 0 | Y31: =Таблица6[[#This Row],[Столбец21]]/Таблица6[[#This Row],[Столбец13]] -> #DIV/0!
A32: 31 | C32: =spisok!B32 -> ЛАДА 213100 4х4 | D32: =spisok!C32 -> В473ЕР126 | E32: =spisok!D32 -> XTA213100G0177506 | F32: =spisok!G32 -> 283293 | G32: =spisok!F32 -> 2015 | H32: =spisok!H32 -> 46184 | I32: =spisok!E32 -> 106-63 | J32: 31 | K32: ="00"&TEXT($L32,"0")&"-10" -> 0031-10 | L32: 31
A33: 32 | C33: =spisok!B33 -> VOLKSWAGEN MULTIVEN | D33: =spisok!C33 -> С488ВС15 | E33: =spisok!D33 -> XW8ZZZ7HZDG001346 | F33: =spisok!E33 -> 101-90 | G33: =spisok!F33 -> 2013 | H33: =spisok!G33 -> 302107 | I33: =spisok!H33 -> 46184 | J33: 32 | K33: ="00"&TEXT($L33,"0")&"-10" -> 0032-10 | L33: 32 | P33: =Таблица6[[#This Row],[Столбец11]]+Таблица6[[#This Row],[Столбец12]] -> 0 | X33: =Таблица6[[#This Row],[Столбец16]]-Таблица6[[#This Row],[Столбец13]] -> 0 | Y33: =Таблица6[[#This Row],[Столбец21]]/Таблица6[[#This Row],[Столбец13]] -> #DIV/0!
A34: 33 | C34: =spisok!B34 -> ЕСАУЛ 394511-03 | D34: =spisok!C34 -> Е368НТ15 | E34: =spisok!D34 -> X8939451CK0AK5323 | F34: =spisok!E34 -> 104-95 | G34: =spisok!F34 -> 2019 | H34: =spisok!G34 -> 139503 | I34: =spisok!H34 -> 46185 | J34: 33 | K34: ="00"&TEXT($L34,"0")&"-10" -> 0033-10 | L34: 33 | P34: =Таблица6[[#This Row],[Столбец11]]+Таблица6[[#This Row],[Столбец12]] -> 0 | X34: =Таблица6[[#This Row],[Столбец16]]-Таблица6[[#This Row],[Столбец13]] -> 0 | Y34: =Таблица6[[#This Row],[Столбец21]]/Таблица6[[#This Row],[Столбец13]] -> #DIV/0!
A35: 34 | J35: 34 | K35: ="00"&TEXT($L35,"0")&"-10" -> 0034-10 | L35: 34 | P35: =Таблица6[[#This Row],[Столбец11]]+Таблица6[[#This Row],[Столбец12]] -> 0 | X35: =Таблица6[[#This Row],[Столбец16]]-Таблица6[[#This Row],[Столбец13]] -> 0 | Y35: =Таблица6[[#This Row],[Столбец21]]/Таблица6[[#This Row],[Столбец13]] -> #DIV/0!
J36: 35 | K36: ="00"&TEXT($L36,"0")&"-10" -> 0035-10 | L36: 35 | P36: =Таблица6[[#This Row],[Столбец11]]+Таблица6[[#This Row],[Столбец12]] -> 0 | X36: =Таблица6[[#This Row],[Столбец16]]-Таблица6[[#This Row],[Столбец13]] -> 0 | Y36: =Таблица6[[#This Row],[Столбец21]]/Таблица6[[#This Row],[Столбец13]] -> #DIV/0!
A37: 36 | J37: 36 | K37: ="00"&TEXT($L37,"0")&"-10" -> 0036-10 | L37: 36 | P37: =Таблица6[[#This Row],[Столбец11]]+Таблица6[[#This Row],[Столбец12]] -> 0 | X37: =Таблица6[[#This Row],[Столбец16]]-Таблица6[[#This Row],[Столбец13]] -> 0 | Y37: =Таблица6[[#This Row],[Столбец21]]/Таблица6[[#This Row],[Столбец13]] -> #DIV/0!
A38: 37 | J38: 37 | K38: ="00"&TEXT($L38,"0")&"-10" -> 0037-10 | L38: 37 | P38: =Таблица6[[#This Row],[Столбец11]]+Таблица6[[#This Row],[Столбец12]] -> 0 | X38: =Таблица6[[#This Row],[Столбец16]]-Таблица6[[#This Row],[Столбец13]] -> 0 | Y38: =Таблица6[[#This Row],[Столбец21]]/Таблица6[[#This Row],[Столбец13]] -> #DIV/0!
A39: 38 | J39: 38 | K39: ="00"&TEXT($L39,"0")&"-10" -> 0038-10 | L39: 38 | P39: =Таблица6[[#This Row],[Столбец11]]+Таблица6[[#This Row],[Столбец12]] -> 0 | X39: =Таблица6[[#This Row],[Столбец16]]-Таблица6[[#This Row],[Столбец13]] -> 0 | Y39: =Таблица6[[#This Row],[Столбец21]]/Таблица6[[#This Row],[Столбец13]] -> #DIV/0!
A40: 39 | J40: 39 | K40: ="00"&TEXT($L40,"0")&"-10" -> 0039-10 | L40: 39 | P40: =Таблица6[[#This Row],[Столбец11]]+Таблица6[[#This Row],[Столбец12]] -> 0 | X40: =Таблица6[[#This Row],[Столбец16]]-Таблица6[[#This Row],[Столбец13]] -> 0 | Y40: =Таблица6[[#This Row],[Столбец21]]/Таблица6[[#This Row],[Столбец13]] -> #DIV/0!
A41: 40 | J41: 40 | K41: ="00"&TEXT($L41,"0")&"-10" -> 0040-10 | L41: 40 | P41: =Таблица6[[#This Row],[Столбец11]]+Таблица6[[#This Row],[Столбец12]] -> 0 | X41: =Таблица6[[#This Row],[Столбец16]]-Таблица6[[#This Row],[Столбец13]] -> 0 | Y41: =Таблица6[[#This Row],[Столбец21]]/Таблица6[[#This Row],[Столбец13]] -> #DIV/0!
A42: 41 | J42: 41 | K42: ="00"&TEXT($L42,"0")&"-10" -> 0041-10 | L42: 41 | P42: =Таблица6[[#This Row],[Столбец11]]+Таблица6[[#This Row],[Столбец12]] -> 0 | X42: =Таблица6[[#This Row],[Столбец16]]-Таблица6[[#This Row],[Столбец13]] -> 0 | Y42: =Таблица6[[#This Row],[Столбец21]]/Таблица6[[#This Row],[Столбец13]] -> #DIV/0!
A43: 42 | J43: 42 | K43: ="00"&TEXT($L43,"0")&"-10" -> 0042-10 | L43: 42 | P43: =Таблица6[[#This Row],[Столбец11]]+Таблица6[[#This Row],[Столбец12]] -> 0 | X43: =Таблица6[[#This Row],[Столбец16]]-Таблица6[[#This Row],[Столбец13]] -> 0 | Y43: =Таблица6[[#This Row],[Столбец21]]/Таблица6[[#This Row],[Столбец13]] -> #DIV/0!
A44: 43 | J44: 43 | K44: ="00"&TEXT($L44,"0")&"-10" -> 0043-10 | L44: 43 | P44: =Таблица6[[#This Row],[Столбец11]]+Таблица6[[#This Row],[Столбец12]] -> 0 | X44: =Таблица6[[#This Row],[Столбец16]]-Таблица6[[#This Row],[Столбец13]] -> 0 | Y44: =Таблица6[[#This Row],[Столбец21]]/Таблица6[[#This Row],[Столбец13]] -> #DIV/0!
A45: 44 | J45: 1 | K45: ="00"&TEXT($L45,"0")&"-10" -> 0044-10 | L45: 44 | P45: =Таблица6[[#This Row],[Столбец11]]+Таблица6[[#This Row],[Столбец12]] -> 0 | X45: =Таблица6[[#This Row],[Столбец16]]-Таблица6[[#This Row],[Столбец13]] -> 0 | Y45: =Таблица6[[#This Row],[Столбец21]]/Таблица6[[#This Row],[Столбец13]] -> #DIV/0!
A46: 45 | J46: 2 | K46: ="00"&TEXT($L46,"0")&"-10" -> 0045-10 | L46: 45 | P46: =Таблица6[[#This Row],[Столбец11]]+Таблица6[[#This Row],[Столбец12]] -> 0 | X46: =Таблица6[[#This Row],[Столбец16]]-Таблица6[[#This Row],[Столбец13]] -> 0 | Y46: =Таблица6[[#This Row],[Столбец21]]/Таблица6[[#This Row],[Столбец13]] -> #DIV/0!
A47: 46 | J47: 3 | K47: ="00"&TEXT($L47,"0")&"-10" -> 0046-10 | L47: 46 | P47: =Таблица6[[#This Row],[Столбец11]]+Таблица6[[#This Row],[Столбец12]] -> 0 | X47: =Таблица6[[#This Row],[Столбец16]]-Таблица6[[#This Row],[Столбец13]] -> 0 | Y47: =Таблица6[[#This Row],[Столбец21]]/Таблица6[[#This Row],[Столбец13]] -> #DIV/0!
A48: 47 | J48: 4 | K48: ="00"&TEXT($L48,"0")&"-10" -> 0047-10 | L48: 47 | P48: =Таблица6[[#This Row],[Столбец11]]+Таблица6[[#This Row],[Столбец12]] -> 0 | X48: =Таблица6[[#This Row],[Столбец16]]-Таблица6[[#This Row],[Столбец13]] -> 0 | Y48: =Таблица6[[#This Row],[Столбец21]]/Таблица6[[#This Row],[Столбец13]] -> #DIV/0!
... A91: 90 | J91: 16 | K91: ="00"&TEXT($L91,"0")&"-10" -> 0090-10 | L91: 90 | P91: =Таблица6[[#This Row],[Столбец11]]+Таблица6[[#This Row],[Столбец12]] -> 0 | X91: =Таблица6[[#This Row],[Столбец16]]-Таблица6[[#This Row],[Столбец13]] -> 0 | Y91: =Таблица6[[#This Row],[Столбец21]]/Таблица6[[#This Row],[Столбец13]] -> #DIV/0!
A92: 91 | J92: 17 | K92: ="00"&TEXT($L92,"0")&"-10" -> 0091-10 | L92: 91 | X92: =Таблица6[[#This Row],[Столбец16]]-Таблица6[[#This Row],[Столбец13]] -> 0
A93: 92 | J93: 18 | K93: ="00"&TEXT($L93,"0")&"-10" -> 0092-10 | L93: 92 | P93: =Таблица6[[#This Row],[Столбец11]]+Таблица6[[#This Row],[Столбец12]] -> 0 | X93: =Таблица6[[#This Row],[Столбец16]]-Таблица6[[#This Row],[Столбец13]] -> 0 | Y93: =Таблица6[[#This Row],[Столбец21]]/Таблица6[[#This Row],[Столбец13]] -> #DIV/0!
A94: 93 | J94: 19 | K94: ="00"&TEXT($L94,"0")&"-10" -> 0093-10 | L94: 93 | P94: =Таблица6[[#This Row],[Столбец11]]+Таблица6[[#This Row],[Столбец12]] -> 0 | X94: =Таблица6[[#This Row],[Столбец16]]-Таблица6[[#This Row],[Столбец13]] -> 0 | Y94: =Таблица6[[#This Row],[Столбец21]]/Таблица6[[#This Row],[Столбец13]] -> #DIV/0!
A95: 94 | J95: 20 | K95: ="00"&TEXT($L95,"0")&"-10" -> 0094-10 | L95: 94 | P95: =Таблица6[[#This Row],[Столбец11]]+Таблица6[[#This Row],[Столбец12]] -> 0 | X95: =Таблица6[[#This Row],[Столбец16]]-Таблица6[[#This Row],[Столбец13]] -> 0 | Y95: =Таблица6[[#This Row],[Столбец21]]/Таблица6[[#This Row],[Столбец13]] -> #DIV/0!
A96: 95 | J96: 21 | K96: ="00"&TEXT($L96,"0")&"-10" -> 0095-10 | L96: 95 | P96: =Таблица6[[#This Row],[Столбец11]]+Таблица6[[#This Row],[Столбец12]] -> 0 | X96: =Таблица6[[#This Row],[Столбец16]]-Таблица6[[#This Row],[Столбец13]] -> 0 | Y96: =Таблица6[[#This Row],[Столбец21]]/Таблица6[[#This Row],[Столбец13]] -> #DIV/0!
A97: 96 | J97: 22 | K97: ="00"&TEXT($L97,"0")&"-10" -> 0096-10 | L97: 96 | P97: =Таблица6[[#This Row],[Столбец11]]+Таблица6[[#This Row],[Столбец12]] -> 0 | X97: =Таблица6[[#This Row],[Столбец16]]-Таблица6[[#This Row],[Столбец13]] -> 0 | Y97: =Таблица6[[#This Row],[Столбец21]]/Таблица6[[#This Row],[Столбец13]] -> #DIV/0!
...

Sheet spisok
A1: № п/п | B1: Модель | C1: ГРЗ | D1: VIN | E1: гараж. № | F1: год вып. | G1: пробег | H1: дата | I1: № акта ЕИС | J1: сумма
A2: 1 | B2: УАЗ UAZ PATRIOT 3163 | C2: О201МК126 | D2: XTT316300R1000091 | E2: 106-81 | F2: 2023 | G2: 4116 | H2: 46174
A3: 2 | B3: LADA VESTA GFL110 | C3: Е833ОЕ15 | D3: XTAGFL110LY378838 | E3: 104-61 | F3: 2019 | G3: 237856 | H3: 46175
A4: 3 | B4: ЕСАУЛ 394511-03 | C4: В723УУ15 | D4: X8939451CG0AK5370 | E4: 103-30 | F4: 2016 | G4: 142626 | H4: 46175
A5: 4 | B5: LADA VESTA GFL110 | C5: Е378ОУ15 | D5: XTAGFL110LY443715 | E5: 105-48 | F5: 2020 | G5: 209733 | H5: 46176
A6: 5 | B6: ЕСАУЛ 394511-03 | C6: Е506НТ15 | D6: X8939451CK0AK5346 | E6: 104-91 | F6: 2019 | G6: 138364 | H6: 46176 | K6: ЕСАУЛ 394511-03 | L6: Е506НТ15 | O6: ГАЗ 221717 | P6: Е601РА15
A7: 6 | B7: LADA VESTA GFL110 | C7: В211ОХ15 | D7: XTAGFL110JY197249 | E7: 103-75 | F7: 2018 | G7: 320689 | H7: 46176 | O7: LADA GRANTA 219010 | P7: Е559НТ15
A8: 7 | B8: TOYOTA CAMRY ASV70L-RE | C8: Е778РА15 | D8: XW7BF4HK905167068 | E8: 106-39 | F8: 2020 | G8: 40010 | H8: 46176 | L8: TOYOTA CAMRY ASV70L-RE | M8: Е778РА15 | O8: УАЗ ПАТРИОТ | P8: В782ОХ15
A9: 8 | B9: ЛАДА ГРАНТА 219010 | C9: А287АР126 | D9: XTA219010E0256411 | E9: 106-34 | F9: 2014 | G9: 356419 | H9: 46177 | O9: ЛАДА 213100 4х4 | P9: В473ЕР126
A10: 9 | B10: LADA 4x4 213100 | C10: О 0708/15 | D10: XTA213100L0213886 | E10: 104-90 | F10: 2019 | G10: 126256 | H10: 46177
A11: 10 | B11: LADA PRIORA 217050 | C11: Т158АЕ15 | D11: XTA217050G0529350 | E11: 102-89 | F11: 2015 | G11: 275410 | H11: 46177 | K11: LADA PRIORA 217050 | L11: Т158АЕ15
A12: 11 | B12: ТОЙОТА КАМРИ | C12: Е898НТ15 | D12: XW7BF4FK10S155841 | E12: 103-69 | F12: 2017 | G12: 176666 | H12: 46177 | L12: ТОЙОТА КАМРИ | M12: Е898НТ15
A13: 12 | B13: УАЗ 396221 3163 | C13: Е312РА15 | D13: XTT316300M1002503 | E13: 105-57 | F13: 2020 | G13: 108974 | H13: 46178
A14: 13 | B14: ЕСАУЛ 394511-03 | C14: Е368НТ15 | D14: X8939451CK0AK5323 | E14: 104-95 | F14: 2019 | G14: 138585 | H14: 46178
A15: 14 | B15: ЕСАУЛ 394511-03 | C15: Е546НТ15 | D15: X8939451CK0AK5318 | E15: 104-96 | F15: 2019 | G15: 132853 | H15: 46178
A16: 15 | B16: ГАЗ 27322Е | C16: О0775/15 | D16: XUY27322EL0000276 | E16: 105-62 | F16: 2020 | G16: 159663 | H16: 46178 | K16: ГАЗ 27322Е | L16: О0775/15
A17: 16 | B17: ГАЗ 38406L | C17: М0629/15 | D17: Z8X38406LD0000147 | E17: 100-68 | F17: 2013 | G17: 201139 | H17: 46179
A18: 17 | B18: LADA GRANTA 219010 | C18: А722НА15 | D18: XTA219010M0770129 | E18: 105-89 | F18: 2021 | G18: 192073 | H18: 46179
A19: 18 | B19: HAVAL F7 CC6475UM09C | C19: Е985ЕН15 | D19: XZGEF04A4PA351278 | E19: 106-74 | F19: 2023 | G19: 22625 | H19: 46179 | K19: HAVAL F7 CC6475UM09C | L19: Е985ЕН15
A20: 19 | B20: LADA VESTA GFL110 | C20: Е154РА15 | D20: XTAGFL110LY443716 | E20: 105-53 | F20: 2020 | G20: 162007 | H20: 46179
A21: 20 | B21: ГАЗ 2705 | C21: В645ОТ15 | D21: X96270500H0824002 | E21: 103-68 | F21: 2016 | G21: 137401 | H21: 46181
A22: 21 | B22: TOYOTA CAMRY GSV70L-REZ | C22: Е301ОУ15 | D22: XW7BZYHK50S111563 | E22: 105-43 | F22: 2020 | G22: 35665 | H22: 46181 | L22: TOYOTA CAMRY GSV70L-REZ | M22: Е301ОУ15
A23: 22 | B23: РЕНО ДАСТЕР | C23: В391ОХ15 | D23: X7LHSRHGN59704684 | E23: 103-79 | F23: 2018 | G23: 142653 | H23: 46182 | K23: РЕНО ДАСТЕР | L23: В391ОХ15
A24: 23 | B24: ФОРД EXPLORER | C24: Е409РС15 | D24: Z6FBXXESWBES15416 | E24: 101-31 | F24: 2014 | G24: 344213 | H24: 46182 | K24: ФОРД EXPLORER | L24: Е409РС15
A25: 24 | B25: ЛАДА 213100 | C25: А678ХМ126 | D25: XTA213100F0171867 | E25: 106-62 | F25: 2015 | G25: 242508 | H25: 46182
A26: 25 | B26: KIA XM FL (SORENTO) | C26: О0774/15 | D26: XWEKU811DKC024995 | E26: 105-55 | F26: 2020 | G26: 21782 | H26: 46182
A27: 26 | B27: ТОЙОТА КАМРИ | C27: А333НА15 | D27: XW7BF4HK10S150796 | E27: 104-73 | F27: 2019 | G27: 232858 | H27: 46183
A28: 27 | B28: ХЕНДЭ СОЛЯРИС | C28: В201УВ15 | D28: Z94CU41DBFR426306 | E28: 102-63 | F28: 2015 | G28: 365954 | H28: 46183
A29: 28 | B29: LADA GRANTA 219010 | C29: Е559НТ15 | D29: XTA219010L0668690 | E29: 105-10 | F29: 2019 | G29: 230918 | H29: 46183
A30: 29 | B30: LADA VESTA GFL110 | C30: А725НА15 | D30: XTAGFL110MY545270 | E30: 106-01 | F30: 2021 | G30: 217051 | H30: 46184
A31: 30 | B31: УАЗ ПАТРИОТ | C31: В787ОХ15 | D31: XTT316300J1023444 | E31: 103-91 | F31: 2018 | G31: 232487 | H31: 46184
A32: 31 | B32: ЛАДА 213100 4х4 | C32: В473ЕР126 | D32: XTA213100G0177506 | E32: 106-63 | F32: 2015 | G32: 283293 | H32: 46184
A33: 32 | B33: VOLKSWAGEN MULTIVEN | C33: С488ВС15 | D33: XW8ZZZ7HZDG001346 | E33: 101-90 | F33: 2013 | G33: 302107 | H33: 46184
A34: 33 | B34: ЕСАУЛ 394511-03 | C34: Е368НТ15 | D34: X8939451CK0AK5323 | E34: 104-95 | F34: 2019 | G34: 139503 | H34: 46185
A35: 34 | B35: ЕСАУЛ 394511-03 | C35: Е499НТ15 | D35: X8939451CK0AK5363 | E35: 105-01 | F35: 2019 | G35: 103143 | H35: 46186
A36: 35 | B36: LADA VESTA GFL110 | C36: Е375ОУ15 | D36: XTAGFL110LY443723 | E36: 105-47 | F36: 2020 | G36: 231159 | H36: 46188
... A71: 70 | B71: ЕСАУЛ 394511-03 | C71: Е491НТ15 | D71: X8939451CK0AK5352 | E71: 105-00 | F71: 2019 | G71: 39309 | H71: 46203
A72: 71
A73: 72
A74: 73
...

Sheet 645
B1: ПОСТАВЩИК: ООО ФИРМА "СИГНАЛ"
B2: адрес: 364031, Чеченская Республика, г.Грозный, ул. Жуковского, д. 18
C4: Заказ-наряд № 100550 от 09.06.2026
B6: Заказчик: Общество с ограниченной ответственностью «Концепт» | H6: адрес заказчика : 364024, ЧР г.Грозный, ул.Назарбаева, д.92, оф. 6-05
B7: Автомобиль : ГАЗ 2705 г/н В 645 ОТ/15
B9: Цена автомототранспортного средства, определяемая по соглашению сторон __________________
B11: Плательщик: Общество с ограниченной ответственностью «Концепт»
B12: ИНН 2014030866 адрес: телефоны: +7 (989) 9002252
N14: в валюте
N15: Руб
C17: Выполненные работы по заказ-наряду № 100550 от 09.06.2026
B19: № | C19: № кат. | D19: Наименование | I19: Кол. оп. | J19: Цена | K19: Норма | L19: н/ч | M19: Всего | N19: в т.ч. НДС
B20: 1 | C20: 2 | D20: 3 | I20: 4 | J20: 5 | K20: 6 | L20: 7 | M20: 8 | N20: 9
B21: 1 | D21: Диагностика ДВС | I21: 1 | J21: 1000 | K21: 1 | L21: Рубль | M21: =J21*I21 -> 1000 | N21: =M21*22/122 -> 180.32787
B22: 2 | D22: Замена компрессии в цилиндрах | I22: 1 | J22: 400 | K22: 1 | L22: Рубль | M22: =J22*I22 -> 400 | N22: =M22*22/122 -> 72.131148
B23: 3 | D23: Замена прокладки ГБЦ | I23: 1 | J23: 8000 | K23: 1 | L23: Рубль | M23: =J23*I23 -> 8000 | N23: =M23*22/122 -> 1442.623
B24: 4 | D24: Проверка ГБЦ на трещину | I24: 1 | J24: 1000 | K24: 1 | L24: Рубль | M24: =J24*I24 -> 1000 | N24: =M24*22/122 -> 180.32787
B25: 5 | D25: Шлифовка ГБЦ | I25: 1 | J25: 1500 | K25: 1 | L25: Рубль | M25: =J25*I25 -> 1500 | N25: =M25*22/122 -> 270.4918
B26: 6 | D26: Притирка клапанов | I26: 1 | J26: 4000 | K26: 1 | L26: Рубль | M26: =J26*I26 -> 4000 | N26: =M26*22/122 -> 721.31148
B27: 7 | D27: Токарные работы | I27: 1 | J27: 1000 | K27: 1 | L27: Рубль | M27: =J27*I27 -> 1000 | N27: =M27*22/122 -> 180.32787
B28: 8 | D28: Замена свечей зажигания | I28: 1 | J28: 400 | K28: 1 | L28: Рубль | M28: =J28*I28 -> 400 | N28: =M28*22/122 -> 72.131148
B29: Итого работ: | I29: 8 | J29: на сумму: | M29: =M21+M22+M23+M24+M25+M26+M27+M28 -> 17300 | N29: =M29*22/122 -> 3119.6721
B31: Семнадцать тысяч триста рублей 00 копеек.
C33: Расходная накладная к заказ-наряду № 100550 от 09.06.2026
B35: № | C35: № кат. | D35: Наименование | J35: Кол-во | K35: Ед.изм. | L35: Цена | M35: Всего | N35: в т.ч. НДС
B36: 1 | C36: 2 | D36: 3 | J36: 4 | K36: 5 | L36: 6 | M36: 7 | N36: 8
B37: 1 | C37: А17ДВРМ | D37: Свечи А17ДВРМ Стандарт "33" 8кл | J37: 1 | K37: кт | L37: 600 | M37: =L37*J37 -> 600 | N37: =M37*22/122 -> 108.19672
B38: 2 | C38: 4216.3707080-23 | D38: Провода высоковольтные ГАЗ-3302,2705 Бизнес дв.УМЗ-4216 ЕВРО-4 кт | J38: 1 | K38: кт | L38: 1150 | M38: =L38*J38 -> 1150 | N38: =M38*22/122 -> 207.37705
B39: 3 | D39: Шланг d=18 силикон 1 м оранж. внутри Technik | J39: 1 | K39: шт | L39: 300 | M39: =L39*J39 -> 300 | N39: =M39*22/122 -> 54.098361
B40: 4 | D40: Шланг d= 8 силикон (бухта 20м) оранж. внутри Technik | J40: 1 | K40: шт | L40: 150 | M40: =L40*J40 -> 150 | N40: =M40*22/122 -> 27.04918
B41: 5 | D41: Кольцо уплотнительное форсунок ВАЗ 106 л.с. (кт 8 шт) | J41: 1 | K41: кт | L41: 150 | M41: =L41*J41 -> 150 | N41: =M41*22/122 -> 27.04918
B42: 6 | C42: 4216.1008080 | D42: Прокладка УМЗ-4213,4216 коллектора УМЗ | J42: 1 | K42: шт | L42: 120 | M42: =L42*J42 -> 120 | N42: =M42*22/122 -> 21.639344
B43: 7 | C43: 24-1007036-01 | D43: Колпачки маслосъемные дв.402,523,513,511,УАЗ (к-т 8шт.) Кирово-Чепецк | J43: 1 | K43: кт | L43: 600 | M43: =L43*J43 -> 600 | N43: =M43*22/122 -> 108.19672
B44: 8 | D44: РК приемной трубы дв.421 ВАТИ-61 (гайки,шпильки,прокладки) "ЭССКО-НН" | J44: 1 | K44: кт | L44: 200 | M44: =L44*J44 -> 200 | N44: =M44*22/122 -> 36.065574
B45: 9 | C45: 103015 | D45: Антифриз Sintec Luxe G12+ red -40 3кг | J45: 1 | K45: кт | L45: 650 | M45: =L45*J45 -> 650 | N45: =M45*22/122 -> 117.21311
B46: 10 | C46: 421-1003020 | D46: Прокладка ГБЦ дв.421 (с герм.) БЦМ | J46: 1 | K46: шт | L46: 580 | M46: =L46*J46 -> 580 | N46: =M46*22/122 -> 104.59016
B47: Итого материалов: | J47: 10 | K47: на сумму: | M47: =M37+M38+M39+M40+M41+M42+M43+M44+M45+M46 -> 4500 | N47: =M47*22/122 -> 811.47541
B49: Четыре тысячи пятьсот рублей 00 копеек
L51: Итого по заказ-наряду : | M51: =M29+M47 -> 21800 | N51: =M51*22/122 -> 3931.1475
B53: Всего по заказ-наряду: Двадцать одна тысяча восемьсот рублей 00 копеек, в т.ч. НДС 22%.
...

Sheet 158
B1: ПОСТАВЩИК: ООО ФИРМА "СИГНАЛ"
B2: адрес: 364031, Чеченская Республика, г.Грозный, ул. Жуковского, д. 18
C4: Заказ-наряд № 100512 от 04.06.2026
B6: Заказчик: Общество с ограниченной ответственностью «Концепт» | H6: адрес заказчика : 364024, ЧР г.Грозный, ул.Назарбаева, д.92, оф. 6-05
B7: Автомобиль : Лада Приора гос. номер: Т158АЕ/15
B9: Цена автомототранспортного средства, определяемая по соглашению сторон __________________
B11: Плательщик: Общество с ограниченной ответственностью «Концепт»
B12: ИНН 2014030866 адрес: телефоны: +7 (989) 9002252
N14: в валюте
N15: Руб
C17: Выполненные работы по заказ-наряду № 100512 от 04.06.2026
B19: № | C19: № кат. | D19: Наименование | I19: Кол. оп. | J19: Цена | K19: Норма | L19: н/ч | M19: Всего | N19: в т.ч. НДС
B20: 1 | C20: 2 | D20: 3 | I20: 4 | J20: 5 | K20: 6 | L20: 7 | M20: 8 | N20: 9
B21: 1 | D21: Замена радиатора охлаждения | I21: 1 | J21: 4000 | K21: 1 | L21: Рубль | M21: =J21*I21 -> 4000 | N21: =M21*22/122 -> 721.31148
B22: 2 | D22: Замена троса капота | I22: 1 | J22: 2000 | K22: 1 | L22: Рубль | M22: =J22*I22 -> 2000 | N22: =M22*22/122 -> 360.65574
B23: 3 | D23: Замена опоры амортизатора | I23: 2 | J23: 1300 | K23: 1 | L23: Рубль | M23: =J23*I23 -> 2600 | N23: =M23*22/122 -> 468.85246
B24: 4 | D24: Замена рулевого наконечника | I24: 2 | J24: 350 | K24: 1 | L24: Рубль | M24: =J24*I24 -> 700 | N24: =M24*22/122 -> 126.22951
B25: 5 | D25: Ремонт свечей зажигания | I25: 1 | J25: 500 | K25: 1 | L25: Рубль | M25: =J25*I25 -> 500 | N25: =M25*22/122 -> 90.163934
B26: 6 | D26: Замена замка капота | I26: 1 | J26: 400 | K26: 1 | L26: Рубль | M26: =J26*I26 -> 400 | N26: =M26*22/122 -> 72.131148
B27: 7 | D27: Диагностика кондиционера с опрессовкой | I27: 1 | J27: 1300 | K27: 1 | L27: Рубль | M27: 1000 | N27: =M27*22/122 -> 180.32787
B28: 8 | D28: Заправка кондиционера | I28: 1 | J28: 4500 | K28: 1 | L28: Рубль | M28: =J28*I28 -> 4500 | N28: =M28*22/122 -> 811.47541
B29: 9 | D29: Ремонт колеса | I29: 1 | J29: 300 | K29: 1 | L29: Рубль | M29: =J29*I29 -> 300 | N29: =M29*22/122 -> 54.098361
B30: 10 | D30: Замена масла и масл фильтра | I30: 1 | J30: 600 | K30: 1 | L30: Рубль | M30: =J30*I30 -> 600 | N30: =M30*22/122 -> 108.19672
B31: 11 | D31: Замена воздушного фильтра | I31: 1 | J31: 200 | K31: 1 | L31: Рубль | M31: =J31*I31 -> 200 | N31: =M31*22/122 -> 36.065574
B32: 12 | D32: Замена топливного фильтра | I32: 1 | J32: 300 | K32: 1 | L32: Рубль | M32: =J32*I32 -> 300 | N32: =M32*22/122 -> 54.098361
B33: 13 | D33: Сход-развал (с рскруткой сход-разв. тяг) | I33: 1 | J33: 2000 | K33: 1 | L33: Рубль | M33: =J33*I33 -> 2000 | N33: =M33*22/122 -> 360.65574
B34: Итого работ: | I34: 15 | J34: на сумму: | M34: =M21+M22+M23+M24+M25+M26+M27+M28+M29+M30+M31+M32+M33 -> 19100 | N34: =M34*22/122 -> 3444.2623
B36: Девятнадцать тысяч сто рублей 00 копеек.
C38: Расходная накладная к заказ-наряду № 100512 от 04.06.2026
B40: № | C40: № кат. | D40: Наименование | J40: Кол-во | K40: Ед.изм. | L40: Цена | M40: Всего | N40: в т.ч. НДС
B41: 1 | C41: 2 | D41: 3 | J41: 4 | K41: 5 | L41: 6 | M41: 7 | N41: 8
B42: 1 | C42: HF708432 | D42: Радиатор охл ВАЗ 2170 алюм. 2-ряд. под кондиц. Halla сборный HOFER | J42: 1 | K42: шт | L42: 3900 | M42: =L42*J42 -> 3900 | N42: =M42*22/122 -> 703.27869
B43: 2 | C43: 614503 | D43: Антифриз Sintec LUXE G12+, 5 кг, красный | J43: 1 | K43: шт | L43: 1000 | M43: =L43*J43 -> 1000 | N43: =M43*22/122 -> 180.32787
B44: 3 | C44: 103015 | D44: Антифриз Sintec Luxe G12+ red -40 3кг | J44: 1 | K44: шт | L44: 650 | M44: =L44*J44 -> 650 | N44: =M44*22/122 -> 117.21311
B45: 4 | C45: 2110-8406010 | D45: Замок капота Приора, Ваз 2110, Нива Шевроле 2123 | J45: 1 | K45: шт | L45: 500 | M45: =L45*J45 -> 500 | N45: =M45*22/122 -> 90.163934
B46: 5 | C46: 21100-8406140-00 | D46: Трос капота ВАЗ 2110, 2111, 2112, 2170, Приора, Автопартнер | J46: 1 | K46: шт | L46: 200 | M46: =L46*J46 -> 200 | N46: =M46*22/122 -> 36.065574
B47: 6 | C47: 2170-2902821-01 11720 | D47: Опора верхняя передней стойки (без подшипника) усиленная 2170 | J47: 2 | K47: шт | L47: 650 | M47: =L47*J47 -> 1300 | N47: =M47*22/122 -> 234.42623
B48: 7 | C48: 11180-2902840-01 | D48: Подшипник опоры передней стойки 1118 Калина 2170 Priora 2190 Granta LADA Image | J48: 2 | K48: шт | L48: 950 | M48: =L48*J48 -> 1900 | N48: =M48*22/122 -> 342.62295
B49: 8 | C49: AP31-110 | D49: Отбойник амортизатора передний с пыльником Ваз 2110 HOLA | J49: 2 | K49: шт | L49: 350 | M49: =L49*J49 -> 700 | N49: =M49*22/122 -> 126.22951
B50: 9 | C50: LL0108 | D50: Крышка расширительного бачка для а/м Газель Бизнес, ВАЗ 2108/2110/Приора/Гранта LUZAR | J50: 1 | K50: шт | L50: 250 | M50: =L50*J50 -> 250 | N50: =M50*22/122 -> 45.081967
...

Sheet TANK M083277
A1: Заказ-наряд № 100087 от 22.02.2026
A2: Заказчик: Общество с ограниченной ответственностью «Концепт» | B2: адрес заказчика : 364024, ЧР г.Грозный, ул.Назарбаева, д.92, оф. 6-05
A3: Автомобиль : TANK гос. номер: М 0832 77
A5: Выполненные работы по заказ-наряду № 100087 от 22.02.2026
A6: № | B6: № кат. | C6: Наименование | D6: Кол. оп. | E6: Цена | F6: Норма | G6: н/ч | H6: Всего | I6: в т.ч. НДС
A7: 1 | B7: 2 | C7: 3 | D7: 4 | E7: 5 | F7: 6 | G7: 7 | H7: 8 | I7: 9
A8: 1 | C8: Шиномонтаж колеса (снять колесо,сборка-разборка, балансировка, поставить колесо) 1 шт. | D8: 4 | E8: 1250,00 | F8: 1.000 | G8: Рубль | H8: 5 000.00 | I8: 901 64
A9: итого работ: | D9: 4 | E9: на сумму. | H9: 5 000,00 | I9: 901,64
A11: Расходная накладная к заказ-наряду № 100087 от 22.02.2026
A12: № | B12: № кат. | C12: Наименование | D12: Кол-во | E12: Ед.изм. | F12: Цена | G12: Всего | H12: в т.ч. НДС
A13: 1 | B13: 2 | C13: 3 | D13: 4 | E13: 5 | F13: 6 | G13: 7 | H13: 8
A15: итого материалов: | D15: 1 | E15: на сумму: | G15: 0,00 | H15: 0,00

Sheet 62
A1: Акт № 62 от 9 апреля 2026 г. Исполнитель: ООО ФИРМА "СИГНАЛ", ИНН 2014025023, КПП 201401001, 364037, Респ Чеченская, г Грозный, р-н АхматовскИй, ул нм Жуковского, двлд 18, р/с 40702810234120000061, в банке ЧЕЧЕНСКИЙ РФ АО "РОССЕЛЬХОЗБАНк" Г. Грозный, БИК 049690719, к/с 30101810600000000719 Заказчик: ООО "К0НЦЕПТ", ИНН 2014030866, КПП 201401001, 364024, Респ Чеченская, г Грозный, р-н АхматовскИй, ул Н.А.Назарбаева, дом 92, офнс 6-05, р/с 40702810910001078622, в банке АО "ТБанк" Г. Москва, БИК 044525974, к/с 30101810145250000974 Оенование: ДОГОВОР № 05/05-2025 от "27" мая 2025 г.
A2: № | B2: НаИменованИе работ, услуг | C2: Кол-во | D2: Ед. | E2: Цена | F2: Сумма
A3: 1 | B3: Шиномонтаж а/м HAVAL F7 г/н Е 985 ЕН 15 | C3: 1 | D3: шт | E3: 4 000,00 | F3: 4 000,00
A4: 2 | B4: Шиномонтаж а/м Тойота Камри г/н Е 898 НТ /15 | C4: 1 | D4: ШТ | E4: 2600 | F4: 2600
A5: 3 | B5: Ремонт а/м УАЗ Патриот Е312РА 15 | C5: 1 | D5: ШТ | E5: 3650 | F5: 3650
A6: 4 | B6: Ремонт а/м УАЗ Патриот г/н В782ОХ 15 | C6: 1 | D6: шт | E6: 62050 | F6: 62050
A7: 5 | B7: Ремонт а/м тойота Камри г/н АЗЗЗНА 15 | C7: 4 | D7: ШТ | E7: 7600 | F7: 30400
A8: 6 | B8: Ремонт а/м УАЗ Хантер г/н М 516 PT 15 | C8: 1 | D8: шт | E8: 13000 | F8: 13000
D9: в | E9: Итого: том ЧИсле НДС | F9: 115 700,00 20 863,93

Sheet 516
A1: Заказ-наряд № 100158 от 27.03.2026
A2: Заказчик: Общество с ограниченной ответственностью «Концепт» | B2: адрес заказчика : 364024, ЧР г.Грозный, ул.Назарбаева, д,92, оф. 6-05
A3: Автомобиль : УАЗ Хантер гос. номер: М 516 РТ 15
A5: Выполненные работы по заказ-наряду № 100158 от 27.03.2026
A6: № | B6: № кат. | C6: Наименование | D6: Кол. оп. | E6: Цена | F6: Норма | G6: н/ч | H6: Всего | I6: в т.ч. НДС
A7: 1 | B7: 2 | C7: 3 | D7: 4 | E7: 5 | F7: 6 | G7: 7 | H7: 8 | I7: 9
A8: 1 | C8: Замена муфты включения переднего моста | D8: 2 | E8: 500 | F8: 1 | G8: Рубль | H8: 1000 | I8: 180.33
A9: Итого работ: | D9: 2 | E9: на сумму: | H9: 1000 | I9: 180.33
A11: Расходная накладная к заказ-наряду № 100158 от 27.03.2026
A12: № | B12: № кат. | C12: Наименование | D12: Кол-во | E12: Ед.изм. | F12: Цена | G12: Всего | H12: в т.ч. НДС
A13: 1 | B13: 2 | C13: 3 | D13: 4 | E13: 5 | F13: 6 | G13: 7 | H13: 8
A14: 1 | B14: RB-31512-2304310- 10 | C14: Муфты включения переднего моста (хабы колесные) УАЗ 3163/Патриот469/452/Хантер Серия City "redBTR" кт 2 шт. | D14: 1 | E14: кт | F14: 12000 | G14: 12000 | H14: 2163.93
A15: Итого материалов: | D15: 1 | E15: на сумму: | G15: 12 000,00 | H15: 2163.93

Sheet 333
A1: Закаэ-наряд № 100167 от 04.04.2026
A2: Заказчик: Общество с отраниченной ответственностью «Концепт» | B2: адрес заказчика : 364024, ЧР г,Грозный, ул.назарбаева, д.92, оф. 6-05
A3: Автомобиль : тойота Камри гос. номер: А 333 НА 15
A5: Не | B5: Выполненные Nt хат. | C5: работы по заказ-наряду № 100167 от 04.04.202 Нвимвкив«мио | D5: 6 КОЛ. оп. | E5: цена | F5: Норме | G5: н/ч | H5: Всего | I5: в т.ч. НДС
A6: 1 | B6: 2 | C6: 3 | D6: 4 | E6: 5 | F6: в | G6: 7 | H6: 8 | I6: 9
A7: 1 | C7: Балансировка колеса (со с/у) | D7: 4 | E7: 450 | F7: 1 | G7: Рубль | H7: 1800 | I7: 324.59
A8: Итого работ: | D8: * | E8: на сумму: | H8: 1800 | I8: 324.59
A10: № | B10: Расходная наш №кат. | C10: ладная к заказ-наряду № 100167 от 04.04.2026 Наименование | D10: Кол-во | E10: Едизм, | F10: цена | G10: всего | H10: в т.ч. НДС
A11: 1 | B11: 2 | C11: 3 | D11: 4 | E11: 5 | F11: 6 | G11: 7 | H11: 8
A12: 1 | C12: колодки тормозные перед. Kashiyama Toyota Camry V70 17- /RAV 4 | D12: 1 | E12: кт | F12: 3500 | G12: 3500 | H12: 631.15
A13: 2 | C13: КОГОДки тормозные задние D2349H TOYOTA CAMRY (17-). RAV4 (18-). СН-R (18-). LEXUS RX (15-) KASHIYAMA | D13: 1 | E13: кт | F13: 2300 | G13: 2300 | H13: 414.75
A14: ИтоГО материалов: | D14: 2 | E14: на сумму: | G14: 5800 | H14: 1045.9

Sheet 312
A1: Заказ-наряд № 100164 от 01.04.2026
A2: Заказчик: Общество с ограниченной ответственностью «Концепт» | B2: адрес заказчика : 364024, ЧР г.Грозный, ул.назарбаева, д.92, оф. 6-05
A3: Автомобиль : УАЗ патриот гос. номер: Е312РА 15
A5: Выполненные работы по заказ-наряду № 100164 от 01.04.2026
A6: № | B6: №кат. | C6: наименование | D6: Кол. оп. | E6: Цена | F6: Норма | G6: н/ч | H6: всего | I6: в т.ч. ндс
A7: 1 | B7: 2 | C7: 3 | D7: 4 | E7: 8 | F7: 6 | G7: 7 | H7: 8 | I7: 9
A8: 1 | C8: Диагностика ДВС | D8: 1 | E8: 1000 | F8: 1 | G8: Рубль | H8: 1000 | I8: 180.33
A9: 2 | C9: Ремонт электрооборудования | D9: 1 | E9: 1150 | F9: 1 | G9: Рубль | H9: 1150 | I9: 207.38
A10: 3 | C10: сход-развал | D10: 1 | E10: 1500 | F10: 1 | G10: Рубль | H10: 1500 | I10: 270.49
A11: Итото работ: | D11: 3 | E11: на сумму: | H11: 3650 | I11: 658.2
A13: Расходная накладная к заказ-наряду № 100164 от 01.04,2026
A14: № | B14: № кат. | C14: Наименование | D14: Кол-во | E14: Ед.изм. | F14: Цена | G14: Всего | H14: в т.ч. НДС
A15: 1 | B15: 2 | C15: 3 | D15: 4 | E15: 5 | F15: 6 | G15: 7 | H15: 8
A17: Итото материалов: | D17: 0 | E17: на сумму:

Sheet 782
A1: Заказ-наряд № 100156 от 27.03.2026
A2: Заказчик: Общество с ограниченной ответственностью «Концепт» | B2: адрес заказчика : 364024, ЧР г.Грозный, ул.назарбаева, д.92, оф, 6-05
A3: Автомобиль : УАЗ Патриот гос, номер: В782ОХ 15
A5: Выполненные работы по заказ-наряду № 100156 от 27.03.2026
A6: № | B6: №кат. | C6: Наименование | D6: Кол, оп. | E6: Цена | F6: Норма | G6: н/ч | H6: Всего | I6: в т.ч. НДС
A7: 1 | B7: 2 | C7: 3 | D7: 4 | E7: 5 | F7: 6 | G7: 7 | H7: 8 | I7: 9
A8: 1 | C8: Замена масла и масл фильтра ГУР | D8: 1 | E8: 600 | F8: 1 | G8: Рубль | H8: 600 | I8: 108.2
A9: 2 | C9: Подтяжка шкворня | D9: 2 | E9: 800 | F9: 1 | G9: Рубль | H9: 1600 | I9: 288.52
A10: 3 | C10: Подтяжка хвостовика | D10: 1 | E10: 500 | F10: 1 | G10: Рубль | H10: 500 | I10: 90.16
A11: 4 | C11: Ремонт выхлопной системы | D11: 1 | E11: 500 | F11: 1 | G11: Рубль | H11: 500 | I11: 90.16
A12: 5 | C12: Замена рулевого механизма | D12: 1 | E12: 2500 | F12: 1 | G12: Рубль | H12: 2500 | I12: 450.82
A13: 6 | C13: Замена рулевого кардана | D13: 1 | E13: 500 | F13: 1 | G13: Рубль | H13: 500 | I13: 90.16
A14: 7 | C14: Замена подрулевого шлейфа | D14: 1 | E14: 1500 | F14: 1 | G14: Рубль | H14: 1500 | I14: 270.49
A15: 8 | C15: Диагностика и ремонт электрооборудования | D15: 1 | E15: 2500 | F15: 1 | G15: Рубль | H15: 2500 | I15: 450.82
A16: Итого работ: | D16: 9 | E16: на сумму: | H16: 10200 | I16: 1839.34
A18: Расходная накладная к заказ-наряду № 100156 от 27.03.2026
A19: № | B19: № кат. | C19: Наименование | D19: Кол-во | E19: Ед.изм. | F19: Цена | G19: Всего | H19: в т.ч. НДС
A20: 1 | B20: 2 | C20: 3 | D20: 4 | E20: 5 | F20: 6 | G20: 7 | H20: 8
A21: 1 | B21: ЕКО0262 | C21: Фильтр масляный в гидроусилитель ЕКО-02,62 (Камаз, ЗиЛ, Волга, ГАЗ) | D21: 1 | E21: шт | F21: 200 | G21: 200 | H21: 36.07
A22: 2 | B22: 30466 | C22: Масло трансмиссионное Kinetik Energy ATF Luxe Dexron III ч/с 1л | D22: 2 | E22: шт | F22: 400 | G22: 800 | H22: 144.26
A23: 3 | B23: 3163-3400500-10 | C23: Рулевое управление (механизмГУРа) для Патриот под мелкий шлиц YuBei | D23: 1 | E23: шт | F23: 40000 | G23: 40000 | H23: 7213.11
A24: 4 | B24: 316310-3401400-00 | C24: Вал карданный УАЗ-3163 (14-) рулевой в сборе под ГУР YB (ОАО УАЗ) | D24: 1 | E24: шт | F24: 6500 | G24: 6500 | H24: 1172.13
A25: 5 | B25: ORTRA185 | C25: Шлейф подрулевой для UAZ PATRIOT 2016-2025 , UAZ PICKUP 2016-2025 , UAZ PATRIOT 3163 20162025 | D25: 1 | E25: шт | F25: 4350 | G25: 4350 | H25: 784.43
A26: Итого материалов: | D26: 6 | E26: на сумму: | G26: 51850 | H26: 9350

Sheet 72
A1: Акт № 72 от 23 апреля 2026 Г.
A2: Исполнитель: ООО ФИРМА "СИГНАЛ", ИНН 2014025023, КПП 201401001, 364037, Респ Чеченская, г Грозный, р-н Ахматовский, ул нм Жуковского, двлд 18, р/с 40702810234120000061, в банке ЧЕЧЕНСКИЙ РФ АО "РОССЕЛЬХОЗБАНК" Г. Грозный, БИК 049690719, к/с 30101810600000000719 Заказчик: ООО "КОНЦЕПТ", ИНН 2014030866, КПП 201401001, 364024, Респ Чеченская, г Гроэный, р-н АхматовскИй, ул Н.А.Назарбаева, дом 92, офИс 6-05, р/с 40702810910001078622, в банке АО "ТБанк" Г. Москва, БИК 044525974, к/с 30101810145250000974 Основание: ДОГОВОР № 05/05-2025 от "27" мая 2025 г.
A3: № | B3: Наименование работ, услуг | C3: кол-во | D3: ЕД- | E3: Цена | F3: Сумма
A4: 1 | B4: Ремонт а/м УАЗ Патриот г/н X 459 КХ | C4: 1 | D4: ШТ | E4: 81600 | F4: 81600
A5: Итого: 81 600,00 В том ЧИсле НДС 14 714,75

Sheet 459
A1: Закаэ-наряд № 100160 от 27.03.2026
A2: Заказчик: Общество с ограниченной ответственностью «Концепт» | B2: адрес заказчика : 364024, ЧР г.Грозный, ул.назарбаева, д,92, оф. 6-05
A3: Автомобиль : УАЗ патриот гос. номер: X 459 КХ 15
A5: Выполненные работы по заказ-наряду № 100160 от 27.03.2026
A6: ГЛ | B6: № кат. | C6: наименование | D6: Кол. оп. | E6: цена | F6: норма | G6: н/ч | H6: Всего | I6: в т.ч. НДС
A7: 1 | B7: 2 | C7: 3 | D7: 4 | E7: 6 | G7: 7 | H7: 8 | I7: 9
A8: 1 | C8: диагностика ДВС | D8: 1 | E8: 1000 | F8: 1 | G8: Рубль | H8: 1000 | I8: 180.33
A9: 2 | C9: Замена катушки зажигания | D9: 2 | E9: 100 | F9: 1000 | G9: Рубль | H9: 200 | I9: 36.07
A10: 3 | C10: Замена свечей зажиГання | D10: 1 | E10: 60000 | F10: 1000 | G10: Рубль | H10: 600 | I10: 108.2
A11: 4 | C11: Замена радиатора охлаждения | D11: 1 | E11: 2500 | F11: 1000 | G11: Рубль | H11: 2500 | I11: 450.82
A12: 5 | C12: Замена термостата | D12: 1 | E12: 700 | F12: 1000 | G12: Рубль | H12: 700 | I12: 126.23
A13: 6 | C13: Замена радиатора отопителя | D13: 1 | E13: 15000 | F13: 1 | G13: Рубль | H13: 15000 | I13: 2704.92
A14: 7 | C14: Замена дополнительного насоса отопителя | D14: 1 | E14: 500 | F14: 1000 | G14: Рубль | H14: 500 | I14: 90.16
A15: 8 | C15: ДиагносТИка АБС | D15: 1 | E15: 1000 | F15: 1000 | G15: Рубль | H15: 1 ооо.оо | I15: 180.33
A16: 9 | C16: Ремонт тормозной системы | D16: 1 | E16: 250О.СО | F16: 1000 | G16: Рубль | H16: 2 500.00 | I16: 450.82
A17: 10 | C17: Замена вакуумного усилителя | D17: 1 | E17: 1700 СО | F17: 1000 | G17: Рубль | H17: 1700 | I17: 306.56
A18: 11 | C18: Замена заднего рабочего цилиндра | D18: 1 | E18: 500 СО | F18: 1000 | G18: Рубль | H18: 500 | I18: 90.16
A19: 12 | C19: Токарные работы | D19: 1 | E19: 1500,СО | F19: 1000 | G19: Рубль | H19: 1500 | I19: 270.49
A20: 13 | C20: Ремонт электропроводки | D20: 1 | E20: 2000, СО | F20: 1000 | G20: Рубль | H20: 2000 | I20: 360.66
A21: итого работ: | D21: 14 | E21: на сумму: | H21: 29700 | I21: 535574
A23: Расходная накладная к заказ-наряду № 100160 от 27.03.2026
A24: № | B24: №кат. | C24: Наименование | D24: Кол-во | E24: Ед.изм, | F24: цена | G24: Всего | H24: в т.ч, НДС
A25: 1 | B25: 2 | C25: 3 | D25: 4 | E25: 6 | F25: 6 | G25: 7 | H25: 8
A26: 1 | B26: F01H7B0C42-HZ6 | C26: Свечи АУ-17Д8РМ стандарт "33" BA3 2108-70, 3М3 406-409 УМ3 4216 | D26: 1 | E26: кт | F26: 600 | G26: 60000 | H26: 108.2
A27: 2 | B27: 4073/05 | C27: катушка зажигания 405 Евро-3 (модуль) СОАТЭ | D27: 2 | E27: шт | F27: 1900 | G27: 3800 | H27: 685.25
A28: 3 | B28: LRC0363B | C28: Радиатор УА3-3163 алюминиевый да ЗМЗ-409,40904 IVECO EBPO-2.3 LUZAR | D28: 1 | E28: шт | F28: 18500 | G28: 18 500,00 | H28: 3336.07
A29: 4 | B29: GP 10620016 | C29: Термостат ГА3-24.3102.3110,3302.2705, 3151,3160 402,406. КАМА3-5320.4310, КАМА3-7401=60 G-PART | D29: 1 | E29: шт | F29: 460 | G29: 460 | H29: 82.95
A30: 5 | B30: LRH03831B | C30: Радиатор отоп алюм для а/м УАЗ 3163 Патриот (05 2012-)А/С Sanden | D30: 1 | E30: шт | F30: 4000 | G30: 4 000 00 | H30: 721.31
A31: 6 | B31: 32378001 | C31: Электродвигатель отопителя 32.3780-01 АЕ с насосом 12В, 8=18мм ГА3 3110, УАЗ 3742 АвтоЭлектрика | D31: 1 | E31: шт | F31: 1200 | G31: 1200 | H31: 216.39
A32: 7 | C32: трубка тормозная 0=5 L= 460mm | D32: 3 | E32: шт | F32: 260 | G32: 780 | H32: 140.66
A33: 8 | B33: 316300-350500801 | C33: Усилитель вакуумный УА3-3163 Патриот с ГГЦ (Чехия) (ОАО УАЗ) | D33: 1 | E33: шт | F33: 19500 | G33: 19500 | H33: 351639
A34: 9 | B34: СМР9001 | C34: Цилиндр тормозной задний 3302 Campar-autoparts | D34: 1 | E34: шт | F34: 800 | G34: 800 | H34: 144.26
A35: ТО | B35: ET9121820BLKRW | C35: Изолента мерная ABRO 19мм х 18.2м ABRO | D35: 1 | E35: шт | F35: 100 | G35: 100 | H35: 18.03
A36: 11 | B36: 707613 | D36: 2 | E36: шт | F36: 130 | G36: 260 | H36: 46.89
A38: 12 | B38: 614503 | C38: Антифриз Sintec LUXE G12+, 5 кг, красный | D38: 4 2 | E38: шт | F38: 950 | G38: 1900 | H38: 342.62
A39: итого материалов: | D39: 17 | E39: на сумму: | G39: 51900 | H39: 9359.02

Sheet 778
B1: ПОСТАВЩИК: ООО ФИРМА "СИГНАЛ"
B2: адрес: 364031, Чеченская Республика, г.Грозный, ул. Жуковского, д. 18
C4: Заказ-наряд № 100507 от 03.06.2026
B6: Заказчик: Общество с ограниченной ответственностью «Концепт» | H6: адрес заказчика : 364024, ЧР г.Грозный, ул.Назарбаева, д.92, оф. 6-05
B7: Автомобиль : Toyota Camry г/н Е 778 РА /15
B9: Цена автомототранспортного средства, определяемая по соглашению сторон __________________
B11: Плательщик: Общество с ограниченной ответственностью «Концепт»
B12: ИНН 2014030866 адрес: телефоны: +7 (989) 9002252
N14: в валюте
N15: Руб
C17: Выполненные работы по заказ-наряду № 100507 от 03.06.2026
B19: № | C19: № кат. | D19: Наименование | I19: Кол. оп. | J19: Цена | K19: Норма | L19: н/ч | M19: Всего | N19: в т.ч. НДС
B20: 1 | C20: 2 | D20: 3 | I20: 4 | J20: 5 | K20: 6 | L20: 7 | M20: 8 | N20: 9
B21: 1 | D21: Замена масла и масл фильтра | I21: 1 | J21: 700 | K21: 1 | L21: Рубль | M21: =J21*I21 -> 700 | N21: =M21*22/122 -> 126.22951
B22: 2 | D22: Замена салонного фильтра | I22: 1 | J22: 150 | K22: 1 | L22: Рубль | M22: =J22*I22 -> 150 | N22: =M22*22/122 -> 27.04918
B23: 3 | D23: Замена воздушного фильтра | I23: 1 | J23: 150 | K23: 1 | L23: Рубль | M23: =J23*I23 -> 150 | N23: =M23*22/122 -> 27.04918
B24: Итого работ: | I24: 3 | J24: на сумму: | M24: =M21+M22+M23 -> 1000 | N24: =M24*22/122 -> 180.32787
B26: Одна тысяча рублей 00 копеек
C28: Расходная накладная к заказ-наряду № 100507 от 03.06.2026
B30: № | C30: № кат. | D30: Наименование | J30: Кол-во | K30: Ед.изм. | L30: Цена | M30: Всего | N30: в т.ч. НДС
B31: 1 | C31: 2 | D31: 3 | J31: 4 | K31: 5 | L31: 6 | M31: 7 | N31: 8
B32: 1 | C32: TO1191 | D32: Фильтр масляный Alphard Camry Rav4 rx350 highlander Lexus ES Totachi | J32: 1 | K32: шт | L32: 450 | M32: =L32*J32 -> 450 | N32: =M32*22/122 -> 81.147541
B33: 2 | C33: FAP4625C | D33: Фильтр салона угольный TO Camry VIII,RAV4 V 18- Pilenga | J33: 1 | K33: шт | L33: 650 | M33: =L33*J33 -> 650 | N33: =M33*22/122 -> 117.21311
B34: 3 | C34: 08880-86084 | D34: Моторное масло Toyota Synthetic 5W-40, 5л | J34: 1 | K34: шт | L34: 6500 | M34: =L34*J34 -> 6500 | N34: =M34*22/122 -> 1172.1311
B35: 4 | C35: MFA 233 | D35: Фильтр воздушный Camry V70 MASUMA | J35: 1 | K35: шт | L35: 800 | M35: =L35*J35 -> 800 | N35: =M35*22/122 -> 144.2623
B36: Итого материалов: | J36: 4 | K36: на сумму: | M36: =M32+M33+M34+M35 -> 8400 | N36: =M36*22/122 -> 1514.7541
B38: Восемь тысяч четыреста рублей 00 копеек
L40: Итого по заказ-наряду : | M40: =M24+M36 -> 9400 | N40: =M40*20/120 -> 1566.6667
B42: Всего по заказ-наряду: Девять тысяч четыреста рублей 00 копеек, в т.ч. НДС 22%.
J45: Мастер _____________________ | K45: Механик СТО/
C47: Гарантии: Гарантия на работы: слесарные - 30 дней, электрические - 30 дней, оригинальные з/ч - 30 дней, з/ч, связанные с электрооборудованием, подачей топлива и системой впрыска - гарантии нет, неоригинальные з/ч - гарантии нет. Гарантийные обязательства на работы выполняются фирмой только при предъявлении акта приемки автомобиля и техпаспорта (доверенности).
B52: Дата: 03.06.2026 | J52: Заказчик ______________________ | K52: /Общество с ограниченной ответственностью «Концепт»/
J54: Плательщик ______________________ | K54: /Общество с ограниченной ответственностью «Концепт»/
B56: Причина обращения:

Sheet 0629
B1: ПОСТАВЩИК: ООО ФИРМА "СИГНАЛ"
B2: адрес: 364031, Чеченская Республика, г.Грозный, ул. Жуковского, д. 18
C4: Заказ-наряд № 100504 от 02.06.2026
B6: Заказчик: Общество с ограниченной ответственностью «Концепт» | H6: адрес заказчика : 364024, ЧР г.Грозный, ул.Назарбаева, д.92, оф. 6-05
B7: Автомобиль : ГАЗ 384064 гос. номер: О 0629 15
B9: Цена автомототранспортного средства, определяемая по соглашению сторон __________________
B11: Плательщик: Общество с ограниченной ответственностью «Концепт»
B12: ИНН 2014030866 адрес: телефоны: +7 (989) 9002252
N14: в валюте
N15: Руб
C17: Выполненные работы по заказ-наряду № 100504 от 02.06.2026
B19: № | C19: № кат. | D19: Наименование | I19: Кол. оп. | J19: Цена | K19: Норма | L19: н/ч | M19: Всего | N19: в т.ч. НДС
B20: 1 | C20: 2 | D20: 3 | I20: 4 | J20: 5 | K20: 6 | L20: 7 | M20: 8 | N20: 9
B21: 1 | D21: Диагностика ДВС | I21: 1 | J21: 1000 | K21: 1 | L21: Рубль | M21: =J21*I21 -> 1000 | N21: =M21*22/122 -> 180.32787
B22: 2 | D22: Замена муфты электромагнитной | I22: 1 | J22: 1700 | K22: 1 | L22: Рубль | M22: =J22*I22 -> 1700 | N22: =M22*22/122 -> 306.55738
